Workbook

Sheet EmpleadoSesion
A1: employee_session_key | B1: employee_id | C1: session_id | D1: participantes_access_id | E1: participantes_first_name | F1: participantes_job_title | G1: participantes_last_name | H1: participantes_session_access_membership_id | I1: sesiones_description | J1: sesiones_due_date | K1: sesiones_duration | L1: sesiones_ends_at | M1: sesiones_link | N1: sesiones_location | O1: sesiones_modality | P1: sesiones_name | Q1: sesiones_parent_id | R1: sesiones_schedule | S1: sesiones_session_attendance_ids | T1: sesiones_session_feedback_id | U1: sesiones_session_id | V1: sesiones_starts_at | W1: sesiones_status | X1: sesiones_subsidized | Y1: sesiones_training_class_id | Z1: sesiones_training_id | AA1: grupos_cost | AB1: grupos_description | AC1: grupos_end_date | AD1: grupos_indirect_cost | AE1: grupos_name | AF1: grupos_salary_cost | AG1: grupos_start_date | AH1: grupos_subsidized_cost | AI1: grupos_training_class_id | AJ1: grupos_training_id | AK1: cursos_author_id | AL1: cursos_catalog | AM1: cursos_category_ids | AN1: cursos_code | AO1: cursos_company_id | AP1: cursos_competency_ids | AQ1: cursos_cost | AR1: cursos_cost_decimal | AS1: cursos_created_at | AT1: cursos_description | AU1: cursos_external | AV1: cursos_external_provider | AW1: cursos_fundae_subsidized | AX1: cursos_name | AY1: cursos_number_of_expired_participants | AZ1: cursos_objectives | BA1: cursos_status | BB1: cursos_subsidized | BC1: cursos_subsidized_cost | BD1: cursos_subsidized_cost_decimal | BE1: cursos_total_cost | BF1: cursos_total_cost_decimal | BG1: cursos_total_participants | BH1: cursos_total_training_cost | BI1: cursos_total_training_indirect_cost | BJ1: cursos_total_training_salary_cost | BK1: cursos_total_training_subsidized_cost | BL1: cursos_training_attendance_status | BM1: cursos_training_id | BN1: cursos_updated_at | BO1: cursos_valid_for | BP1: cursos_year
A2: 2497090__79325 | B2: 2497090 | C2: 79325 | D2: 2537138 | E2: Immaculada | G2: Rodriguez Molino | H2: 561940 | J2: 38245 | K2: 1.0 | L2: 2004-09-15T23:59:59.000Z | N2: FORMACION INTERNA | O2: inperson | P2: 2004 | R2: selfpaced | S2: [567948] | U2: 79325 | V2: 2004-09-13T00:00:00.000Z | W2: active | X2: FALSO | Y2: 54603 | Z2: 51803 | AA2: 0 | AC2: 38245 | AD2: 0 | AE2: 2004 | AF2: 0 | AG2: 38243 | AH2: 0 | AI2: 54603 | AJ2: 51803 | AK2: 2529034 | AL2: FALSO | AM2: [] | AN2: 9 | AO2: 309418 | AP2: [] | AQ2: 0 | AR2: 0 | AS2: 2025-04-01T07:25:04.674Z | AU2: FALSO | AW2: FALSO | AX2: LOTUS NOTES | BA2: active | BB2: FALSO | BC2: 0 | BD2: 0 | BE2: 0 | BF2: 0 | BG2: 1 | BH2: 0 | BI2: 0 | BJ2: 0 | BK2: 0 | BL2: notstarted | BM2: 51803 | BN2: 2025-04-02T14:00:19.398Z | BP2: 2004
A3: 2497090__79326 | B3: 2497090 | C3: 79326 | D3: 2537138 | E3: Immaculada | G3: Rodriguez Molino | H3: 561941 | J3: 38898 | K3: 0.07 | L3: 2006-06-30T23:59:59.000Z | N3: CIEF | O3: inperson | P3: 2005 | R3: selfpaced | S3: [567949] | U3: 79326 | V3: 2005-10-17T00:00:00.000Z | W3: active | X3: FALSO | Y3: 54604 | Z3: 51808 | AA3: 0 | AC3: 38898 | AD3: 0 | AE3: 2005 | AF3: 0 | AG3: 38642 | AH3: 0 | AI3: 54604 | AJ3: 51808 | AK3: 2529034 | AL3: FALSO | AM3: [] | AN3: 15 | AO3: 309418 | AP3: [] | AQ3: 0 | AR3: 0 | AS3: 2025-04-01T07:25:06.229Z | AU3: VERDADERO | AV3: CIEF | AW3: FALSO | AX3: INGLES PRE-INTERMEDIATE | BA3: active | BB3: FALSO | BC3: 0 | BD3: 0 | BE3: 0 | BF3: 0 | BG3: 1 | BH3: 0 | BI3: 0 | BJ3: 0 | BK3: 0 | BL3: notstarted | BM3: 51808 | BN3: 2025-04-02T14:00:19.656Z | BP3: 2004
A4: 2497090__79327 | B4: 2497090 | C4: 79327 | D4: 2537138 | E4: Immaculada | G4: Rodriguez Molino | H4: 561942 | J4: 39071 | K4: 4.0 | L4: 2006-12-20T23:59:59.000Z | N4: CIEF | O4: inperson | P4: 2006 | R4: selfpaced | S4: [567950] | U4: 79327 | V4: 2006-01-11T00:00:00.000Z | W4: active | X4: FALSO | Y4: 54605 | Z4: 51808 | AA4: 0 | AC4: 39071 | AD4: 0 | AE4: 2006 | AF4: 0 | AG4: 38728 | AH4: 0 | AI4: 54605 | AJ4: 51808 | AK4: 2529034 | AL4: FALSO | AM4: [] | AN4: 15 | AO4: 309418 | AP4: [] | AQ4: 0 | AR4: 0 | AS4: 2025-04-01T07:25:06.229Z | AU4: VERDADERO | AV4: CIEF | AW4: FALSO | AX4: INGLES PRE-INTERMEDIATE | BA4: active | BB4: FALSO | BC4: 0 | BD4: 0 | BE4: 0 | BF4: 0 | BG4: 1 | BH4: 0 | BI4: 0 | BJ4: 0 | BK4: 0 | BL4: notstarted | BM4: 51808 | BN4: 2025-04-02T14:00:19.656Z | BP4: 2004
A5: 2497090__79328 | B5: 2497090 | C5: 79328 | D5: 2537138 | E5: Immaculada | G5: Rodriguez Molino | H5: 561943 | J5: 38497 | K5: 20.0 | L5: 2005-05-25T23:59:59.000Z | N5: AULA BDN, SCP | O5: inperson | P5: 2005 | R5: selfpaced | S5: [567951] | U5: 79328 | V5: 2005-05-23T00:00:00.000Z | W5: active | X5: FALSO | Y5: 54606 | Z5: 51810 | AA5: 248 | AC5: 38497 | AD5: 0 | AE5: 2005 | AF5: 0 | AG5: 38495 | AH5: 0 | AI5: 54606 | AJ5: 51810 | AK5: 2529034 | AL5: FALSO | AM5: [] | AN5: 32 | AO5: 309418 | AP5: [] | AQ5: 0 | AR5: 0 | AS5: 2025-04-01T07:25:06.791Z | AU5: VERDADERO | AV5: AULA BDN, SCP | AW5: FALSO | AX5: HIDROCOLOIDES: ESPESANTES I GELIFICANTES | BA5: active | BB5: FALSO | BC5: 0 | BD5: 0 | BE5: 0 | BF5: 0 | BG5: 1 | BH5: 248 | BI5: 0 | BJ5: 0 | BK5: 0 | BL5: notstarted | BM5: 51810 | BN5: 2025-04-02T14:00:19.942Z | BP5: 2005
A6: 2497090__79329 | B6: 2497090 | C6: 79329 | D6: 2537138 | E6: Immaculada | G6: Rodriguez Molino | H6: 561944 | J6: 39398 | K6: 2.0 | L6: 2007-11-12T23:59:59.000Z | N6: MEGARA SOCIEDAD DE PREVENCIÓN DE MUTUA E | O6: inperson | P6: 2007 | R6: selfpaced | S6: [567952] | U6: 79329 | V6: 2007-11-12T00:00:00.000Z | W6: active | X6: FALSO | Y6: 54607 | Z6: 51811 | AA6: 0 | AC6: 39398 | AD6: 0 | AE6: 2007 | AF6: 0 | AG6: 39398 | AH6: 0 | AI6: 54607 | AJ6: 51811 | AK6: 2529034 | AL6: FALSO | AM6: [] | AN6: 105 | AO6: 309418 | AP6: [] | AQ6: 0 | AR6: 0 | AS6: 2025-04-01T07:25:07.091Z | AU6: VERDADERO | AV6: MEGARA SOCIEDAD DE PREVENCIÓN DE MUTUA E | AW6: FALSO | AX6: PANTALLAS DE VISUALIZACIÓN DE DATOS | BA6: active | BB6: FALSO | BC6: 0 | BD6: 0 | BE6: 0 | BF6: 0 | BG6: 4 | BH6: 0 | BI6: 0 | BJ6: 0 | BK6: 0 | BL6: notstarted | BM6: 51811 | BN6: 2025-04-02T14:00:20.208Z | BP6: 2007
A7: 2497092__79330 | B7: 2497092 | C7: 79330 | D7: 2537140 | E7: ABDELKARIM | G7: BELOUAFI | H7: 561945 | J7: 44266 | K7: 3.0 | L7: 2021-03-11T23:59:59.000Z | N7: GRUPO PREVING | O7: inperson | P7: 2021 | R7: selfpaced | S7: [567953, 567954, 567955] | U7: 79330 | V7: 2021-03-11T00:00:00.000Z | W7: active | X7: FALSO | Y7: 54608 | Z7: 51811 | AA7: 0 | AC7: 44266 | AD7: 0 | AE7: 2021 | AF7: 0 | AG7: 44266 | AH7: 0 | AI7: 54608 | AJ7: 51811 | AK7: 2529034 | AL7: FALSO | AM7: [] | AN7: 105 | AO7: 309418 | AP7: [] | AQ7: 0 | AR7: 0 | AS7: 2025-04-01T07:25:07.091Z | AU7: VERDADERO | AV7: MEGARA SOCIEDAD DE PREVENCIÓN DE MUTUA E | AW7: FALSO | AX7: PANTALLAS DE VISUALIZACIÓN DE DATOS | BA7: active | BB7: FALSO | BC7: 0 | BD7: 0 | BE7: 0 | BF7: 0 | BG7: 4 | BH7: 0 | BI7: 0 | BJ7: 0 | BK7: 0 | BL7: notstarted | BM7: 51811 | BN7: 2025-04-02T14:00:20.208Z | BP7: 2007
A8: 2497095__79330 | B8: 2497095 | C8: 79330 | D8: 2537143 | E8: Francisco | G8: Martin Sabariego | H8: 561946 | J8: 44266 | K8: 3.0 | L8: 2021-03-11T23:59:59.000Z | N8: GRUPO PREVING | O8: inperson | P8: 2021 | R8: selfpaced | S8: [567953, 567954, 567955] | U8: 79330 | V8: 2021-03-11T00:00:00.000Z | W8: active | X8: FALSO | Y8: 54608 | Z8: 51811 | AA8: 0 | AC8: 44266 | AD8: 0 | AE8: 2021 | AF8: 0 | AG8: 44266 | AH8: 0 | AI8: 54608 | AJ8: 51811 | AK8: 2529034 | AL8: FALSO | AM8: [] | AN8: 105 | AO8: 309418 | AP8: [] | AQ8: 0 | AR8: 0 | AS8: 2025-04-01T07:25:07.091Z | AU8: VERDADERO | AV8: MEGARA SOCIEDAD DE PREVENCIÓN DE MUTUA E | AW8: FALSO | AX8: PANTALLAS DE VISUALIZACIÓN DE DATOS | BA8: active | BB8: FALSO | BC8: 0 | BD8: 0 | BE8: 0 | BF8: 0 | BG8: 4 | BH8: 0 | BI8: 0 | BJ8: 0 | BK8: 0 | BL8: notstarted | BM8: 51811 | BN8: 2025-04-02T14:00:20.208Z | BP8: 2007
A9: 2497096__79330 | B9: 2497096 | C9: 79330 | D9: 2537144 | E9: Queralt | G9: Pich Oliveras | H9: 561947 | J9: 44266 | K9: 3.0 | L9: 2021-03-11T23:59:59.000Z | N9: GRUPO PREVING | O9: inperson | P9: 2021 | R9: selfpaced | S9: [567953, 567954, 567955] | U9: 79330 | V9: 2021-03-11T00:00:00.000Z | W9: active | X9: FALSO | Y9: 54608 | Z9: 51811 | AA9: 0 | AC9: 44266 | AD9: 0 | AE9: 2021 | AF9: 0 | AG9: 44266 | AH9: 0 | AI9: 54608 | AJ9: 51811 | AK9: 2529034 | AL9: FALSO | AM9: [] | AN9: 105 | AO9: 309418 | AP9: [] | AQ9: 0 | AR9: 0 | AS9: 2025-04-01T07:25:07.091Z | AU9: VERDADERO | AV9: MEGARA SOCIEDAD DE PREVENCIÓN DE MUTUA E | AW9: FALSO | AX9: PANTALLAS DE VISUALIZACIÓN DE DATOS | BA9: active | BB9: FALSO | BC9: 0 | BD9: 0 | BE9: 0 | BF9: 0 | BG9: 4 | BH9: 0 | BI9: 0 | BJ9: 0 | BK9: 0 | BL9: notstarted | BM9: 51811 | BN9: 2025-04-02T14:00:20.208Z | BP9: 2007
A10: 2497090__79331 | B10: 2497090 | C10: 79331 | D10: 2537138 | E10: Immaculada | G10: Rodriguez Molino | H10: 561948 | J10: 39408 | K10: 8.0 | L10: 2007-11-22T23:59:59.000Z | N10: ASOCIACIÓN DE QUÍMICOS E INGENIEROS | O10: inperson | P10: 2007 | R10: selfpaced | S10: [567956] | U10: 79331 | V10: 2007-11-22T00:00:00.000Z | W10: active | X10: FALSO | Y10: 54609 | Z10: 51812 | AA10: 150 | AC10: 39408 | AD10: 0 | AE10: 2007 | AF10: 0 | AG10: 39408 | AH10: 150 | AI10: 54609 | AJ10: 51812 | AK10: 2529034 | AL10: FALSO | AM10: [] | AN10: 100 | AO10: 309418 | AP10: [] | AQ10: 0 | AR10: 0 | AS10: 2025-04-01T07:25:07.389Z | AU10: VERDADERO | AV10: ASOCIACIÓN DE QUÍMICOS E INGENIEROS | AW10: FALSO | AX10: XI FOOD STUDIES MEETING ON HEALTH AND CHEMISTRY | BA10: active | BB10: FALSO | BC10: 0 | BD10: 0 | BE10: 0 | BF10: 0 | BG10: 1 | BH10: 150 | BI10: 0 | BJ10: 0 | BK10: 150 | BL10: notstarted | BM10: 51812 | BN10: 2025-04-02T14:00:20.604Z | BP10: 2007
A11: 2497090__79332 | B11: 2497090 | C11: 79332 | D11: 2537138 | E11: Immaculada | G11: Rodriguez Molino | H11: 561949 | J11: 39164 | K11: 0.0 | L11: 2007-03-23T23:59:59.000Z | N11: AGÈNCIA CATALANA DE SEGUETAT ALIMENTARIA | O11: inperson | P11: 2007 | R11: selfpaced | S11: [567957] | U11: 79332 | V11: 2007-03-23T00:00:00.000Z | W11: active | X11: FALSO | Y11: 54610 | Z11: 51813 | AA11: 0 | AC11: 39164 | AD11: 0 | AE11: 2007 | AF11: 0 | AG11: 39164 | AH11: 0 | AI11: 54610 | AJ11: 51813 | AK11: 2529034 | AL11: FALSO | AM11: [] | AN11: 92 | AO11: 309418 | AP11: [] | AQ11: 0 | AR11: 0 | AS11: 2025-04-01T07:25:07.757Z | AU11: VERDADERO | AV11: AGÈNCIA CATALANA DE SEGUETAT ALIMENTARIA | AW11: FALSO | AX11: EL REGLAMENT DE DECLARACIONS NUTRICIONALS I DE PROPIETATS SALUDABLES EN ELS ALIM | BA11: active | BB11: FALSO | BC11: 0 | BD11: 0 | BE11: 0 | BF11: 0 | BG11: 1 | BH11: 0 | BI11: 0 | BJ11: 0 | BK11: 0 | BL11: notstarted | BM11: 51813 | BN11: 2025-04-02T14:00:20.960Z | BP11: 2007
A12: 2497090__79333 | B12: 2497090 | C12: 79333 | D12: 2537138 | E12: Immaculada | G12: Rodriguez Molino | H12: 561950 | J12: 39748 | K12: 4.0 | L12: 2008-10-27T23:59:59.000Z | N12: EGARSAT | O12: inperson | P12: 2008 | R12: selfpaced | S12: [567958] | U12: 79333 | V12: 2008-10-27T00:00:00.000Z | W12: active | X12: FALSO | Y12: 54611 | Z12: 51814 | AA12: 0 | AC12: 39748 | AD12: 0 | AE12: 2008 | AF12: 0 | AG12: 39748 | AH12: 0 | AI12: 54611 | AJ12: 51814 | AK12: 2529034 | AL12: FALSO | AM12: [] | AN12: 159 | AO12: 309418 | AP12: [] | AQ12: 0 | AR12: 0 | AS12: 2025-04-01T07:25:08.056Z | AU12: VERDADERO | AV12: EGARSAT | AW12: FALSO | AX12: CONÈIXEMENTS BÀSICS DE SOCORRISME I PRIMERS AUXILIS | BA12: active | BB12: FALSO | BC12: 0 | BD12: 0 | BE12: 0 | BF12: 0 | BG12: 1 | BH12: 0 | BI12: 0 | BJ12: 0 | BK12: 0 | BL12: notstarted | BM12: 51814 | BN12: 2025-04-02T14:00:21.248Z | BP12: 2008
A13: 2497092__79334 | B13: 2497092 | C13: 79334 | D13: 2537140 | E13: ABDELKARIM | G13: BELOUAFI | H13: 561951 | J13: 39770 | K13: 2.0 | L13: 2008-11-18T23:59:59.000Z | N13: EGARSAT | O13: inperson | P13: 2008 | R13: selfpaced | S13: [567959, 567960] | U13: 79334 | V13: 2008-11-18T00:00:00.000Z | W13: active | X13: FALSO | Y13: 54612 | Z13: 51816 | AA13: 0 | AC13: 39770 | AD13: 0 | AE13: 2008 | AF13: 0 | AG13: 39770 | AH13: 0 | AI13: 54612 | AJ13: 51816 | AK13: 2529034 | AL13: FALSO | AM13: [] | AN13: 185 | AO13: 309418 | AP13: [] | AQ13: 0 | AR13: 0 | AS13: 2025-04-01T07:25:08.793Z | AU13: VERDADERO | AV13: EGARSAT | AW13: FALSO | AX13: FORMACIÓ PELS EQUIPS DE PRIMERA INTERVENCIÓ: PREVENCIÓ, EXTINCIÓ I EVACUACIÓ | BA13: active | BB13: FALSO | BC13: 0 | BD13: 0 | BE13: 0 | BF13: 0 | BG13: 2 | BH13: 0 | BI13: 0 | BJ13: 0 | BK13: 0 | BL13: notstarted | BM13: 51816 | BN13: 2025-04-02T14:00:21.588Z | BP13: 2008
A14: 2497093__79334 | B14: 2497093 | C14: 79334 | D14: 2537141 | E14: Fernando J | G14: Urbano Delgado | H14: 561952 | J14: 39770 | K14: 2.0 | L14: 2008-11-18T23:59:59.000Z | N14: EGARSAT | O14: inperson | P14: 2008 | R14: selfpaced | S14: [567959, 567960] | U14: 79334 | V14: 2008-11-18T00:00:00.000Z | W14: active | X14: FALSO | Y14: 54612 | Z14: 51816 | AA14: 0 | AC14: 39770 | AD14: 0 | AE14: 2008 | AF14: 0 | AG14: 39770 | AH14: 0 | AI14: 54612 | AJ14: 51816 | AK14: 2529034 | AL14: FALSO | AM14: [] | AN14: 185 | AO14: 309418 | AP14: [] | AQ14: 0 | AR14: 0 | AS14: 2025-04-01T07:25:08.793Z | AU14: VERDADERO | AV14: EGARSAT | AW14: FALSO | AX14: FORMACIÓ PELS EQUIPS DE PRIMERA INTERVENCIÓ: PREVENCIÓ, EXTINCIÓ I EVACUACIÓ | BA14: active | BB14: FALSO | BC14: 0 | BD14: 0 | BE14: 0 | BF14: 0 | BG14: 2 | BH14: 0 | BI14: 0 | BJ14: 0 | BK14: 0 | BL14: notstarted | BM14: 51816 | BN14: 2025-04-02T14:00:21.588Z | BP14: 2008
... A23: 2497090__79342 | B23: 2497090 | C23: 79342 | D23: 2537138 | E23: Immaculada | G23: Rodriguez Molino | H23: 561961 | J23: 42663 | K23: 13.0 | L23: 2016-10-20T23:59:59.000Z | N23: ASOCIACIÓN ESPAÑOLA DE TÉCNICOS CEREALIS | O23: inperson | P23: 2016 | R23: selfpaced | S23: [567969] | U23: 79342 | V23: 2016-10-19T00:00:00.000Z | W23: active | X23: FALSO | Y23: 54620 | Z23: 51827 | AA23: 350 | AC23: 42663 | AD23: 0 | AE23: 2016 | AF23: 0 | AG23: 42662 | AH23: 0 | AI23: 54620 | AJ23: 51827 | AK23: 2529034 | AL23: FALSO | AM23: [] | AN23: 250 | AO23: 309418 | AP23: [] | AQ23: 0 | AR23: 0 | AS23: 2025-04-01T07:25:11.992Z | AU23: VERDADERO | AV23: ASOCIACION ESPAÑOLA DE TÉCNICOS CEREALIS | AW23: FALSO | AX23: JORNADAS TÉCNICAS DE LA AETC | BA23: active | BB23: FALSO | BC23: 0 | BD23: 0 | BE23: 0 | BF23: 0 | BG23: 1 | BH23: 350 | BI23: 0 | BJ23: 0 | BK23: 0 | BL23: notstarted | BM23: 51827 | BN23: 2025-04-02T14:00:24.418Z | BP23: 2010
A24: 2497092__79343 | B24: 2497092 | C24: 79343 | D24: 2537140 | E24: ABDELKARIM | G24: BELOUAFI | H24: 561962 | J24: 40667 | K24: 2.0 | L24: 2011-05-04T23:59:59.000Z | N24: EGARSAT | O24: inperson | P24: 2011 I | R24: selfpaced | S24: [567970] | U24: 79343 | V24: 2011-05-04T00:00:00.000Z | W24: active | X24: FALSO | Y24: 54621 | Z24: 51830 | AA24: 0 | AC24: 40667 | AD24: 0 | AE24: 2011 I | AF24: 0 | AG24: 40667 | AH24: 0 | AI24: 54621 | AJ24: 51830 | AK24: 2529034 | AL24: FALSO | AM24: [] | AN24: 221 | AO24: 309418 | AP24: [] | AQ24: 0 | AR24: 0 | AS24: 2025-04-01T07:25:13.029Z | AU24: VERDADERO | AV24: EGARSAT | AW24: FALSO | AX24: UTILIZACION DE LOS MEDIOS DE EXTINCION DE INCENDIOS (EXTINTORES Y BIES)-FORMACIO | BA24: active | BB24: FALSO | BC24: 0 | BD24: 0 | BE24: 0 | BF24: 0 | BG24: 2 | BH24: 0 | BI24: 0 | BJ24: 0 | BK24: 0 | BL24: notstarted | BM24: 51830 | BN24: 2025-04-02T14:00:25.033Z | BP24: 2009
A25: 2497093__79344 | B25: 2497093 | C25: 79344 | D25: 2537141 | E25: Fernando J | G25: Urbano Delgado | H25: 561963 | J25: 40681 | K25: 2.0 | L25: 2011-05-18T23:59:59.000Z | N25: EGARSAT | O25: inperson | P25: 2011 II | R25: selfpaced | S25: [567971] | U25: 79344 | V25: 2011-05-18T00:00:00.000Z | W25: active | X25: FALSO | Y25: 54622 | Z25: 51830 | AA25: 0 | AC25: 40681 | AD25: 0 | AE25: 2011 II | AF25: 0 | AG25: 40681 | AH25: 0 | AI25: 54622 | AJ25: 51830 | AK25: 2529034 | AL25: FALSO | AM25: [] | AN25: 221 | AO25: 309418 | AP25: [] | AQ25: 0 | AR25: 0 | AS25: 2025-04-01T07:25:13.029Z | AU25: VERDADERO | AV25: EGARSAT | AW25: FALSO | AX25: UTILIZACION DE LOS MEDIOS DE EXTINCION DE INCENDIOS (EXTINTORES Y BIES)-FORMACIO | BA25: active | BB25: FALSO | BC25: 0 | BD25: 0 | BE25: 0 | BF25: 0 | BG25: 2 | BH25: 0 | BI25: 0 | BJ25: 0 | BK25: 0 | BL25: notstarted | BM25: 51830 | BN25: 2025-04-02T14:00:25.033Z | BP25: 2009
A26: 2497092__79345 | B26: 2497092 | C26: 79345 | D26: 2537140 | E26: ABDELKARIM | G26: BELOUAFI | H26: 561964 | J26: 40667 | K26: 2.0 | L26: 2011-05-04T23:59:59.000Z | N26: EGARSAT | O26: inperson | P26: 2011 I | R26: selfpaced | S26: [567972] | U26: 79345 | V26: 2011-05-04T00:00:00.000Z | W26: active | X26: FALSO | Y26: 54623 | Z26: 51831 | AA26: 0 | AC26: 40667 | AD26: 0 | AE26: 2011 I | AF26: 0 | AG26: 40667 | AH26: 0 | AI26: 54623 | AJ26: 51831 | AK26: 2529034 | AL26: FALSO | AM26: [] | AN26: 158 | AO26: 309418 | AP26: [] | AQ26: 0 | AR26: 0 | AS26: 2025-04-01T07:25:13.355Z | AU26: VERDADERO | AV26: EGARSAT | AW26: FALSO | AX26: EQUIPOS DE EMERGENCIAS: PREVENCIÓN, EXTINCIÓN Y EVACUACION | BA26: active | BB26: FALSO | BC26: 0 | BD26: 0 | BE26: 0 | BF26: 0 | BG26: 2 | BH26: 0 | BI26: 0 | BJ26: 0 | BK26: 0 | BL26: notstarted | BM26: 51831 | BN26: 2025-04-02T14:00:25.360Z | BP26: 2011
A27: 2497093__79346 | B27: 2497093 | C27: 79346 | D27: 2537141 | E27: Fernando J | G27: Urbano Delgado | H27: 561965 | J27: 40681 | K27: 2.0 | L27: 2011-05-18T23:59:59.000Z | N27: EGARSAT | O27: inperson | P27: 2011 II | R27: selfpaced | S27: [567973] | U27: 79346 | V27: 2011-05-18T00:00:00.000Z | W27: active | X27: FALSO | Y27: 54624 | Z27: 51831 | AA27: 0 | AC27: 40681 | AD27: 0 | AE27: 2011 II | AF27: 0 | AG27: 40681 | AH27: 0 | AI27: 54624 | AJ27: 51831 | AK27: 2529034 | AL27: FALSO | AM27: [] | AN27: 158 | AO27: 309418 | AP27: [] | AQ27: 0 | AR27: 0 | AS27: 2025-04-01T07:25:13.355Z | AU27: VERDADERO | AV27: EGARSAT | AW27: FALSO | AX27: EQUIPOS DE EMERGENCIAS: PREVENCIÓN, EXTINCIÓN Y EVACUACION | BA27: active | BB27: FALSO | BC27: 0 | BD27: 0 | BE27: 0 | BF27: 0 | BG27: 2 | BH27: 0 | BI27: 0 | BJ27: 0 | BK27: 0 | BL27: notstarted | BM27: 51831 | BN27: 2025-04-02T14:00:25.360Z | BP27: 2011
A28: 2497090__79347 | B28: 2497090 | C28: 79347 | D28: 2537138 | E28: Immaculada | G28: Rodriguez Molino | H28: 561966 | J28: 41178 | K28: 1.0 | L28: 2012-09-26T23:59:59.000Z | N28: EGARSAT | O28: inperson | P28: 2012 | R28: selfpaced | S28: [567974] | U28: 79347 | V28: 2012-09-26T00:00:00.000Z | W28: active | X28: FALSO | Y28: 54625 | Z28: 51832 | AA28: 0 | AC28: 41178 | AD28: 0 | AE28: 2012 | AF28: 0 | AG28: 41178 | AH28: 0 | AI28: 54625 | AJ28: 51832 | AK28: 2529034 | AL28: FALSO | AM28: [] | AN28: 276 | AO28: 309418 | AP28: [] | AQ28: 0 | AR28: 0 | AS28: 2025-04-01T07:25:13.637Z | AU28: VERDADERO | AV28: EGARSAT | AW28: FALSO | AX28: EQUIPOS DE EMERGENCIA: PREVENCIÓN, EXTINCIÓN Y EVACUACIÓN | BA28: active | BB28: FALSO | BC28: 0 | BD28: 0 | BE28: 0 | BF28: 0 | BG28: 1 | BH28: 0 | BI28: 0 | BJ28: 0 | BK28: 0 | BL28: notstarted | BM28: 51832 | BN28: 2025-04-02T14:00:25.650Z | BP28: 2011
A29: 2497090__79348 | B29: 2497090 | C29: 79348 | D29: 2537138 | E29: Immaculada | G29: Rodriguez Molino | H29: 561967 | J29: 41178 | K29: 1.0 | L29: 2012-09-26T23:59:59.000Z | N29: EGARSAT | O29: inperson | P29: 2012 | R29: selfpaced | S29: [567975] | U29: 79348 | V29: 2012-09-26T00:00:00.000Z | W29: active | X29: FALSO | Y29: 54626 | Z29: 51840 | AA29: 0 | AC29: 41178 | AD29: 0 | AE29: 2012 | AF29: 0 | AG29: 41178 | AH29: 0 | AI29: 54626 | AJ29: 51840 | AK29: 2529034 | AL29: FALSO | AM29: [] | AN29: 274 | AO29: 309418 | AP29: [] | AQ29: 0 | AR29: 0 | AS29: 2025-04-01T07:25:16.114Z | AU29: VERDADERO | AV29: EGARSAT | AW29: FALSO | AX29: UTILIZACIÓN DE LOS MEDIOS DE EXTINCION (BIEs). FORMACIÓN PRÁCTICA | BA29: active | BB29: FALSO | BC29: 0 | BD29: 0 | BE29: 0 | BF29: 0 | BG29: 1 | BH29: 0 | BI29: 0 | BJ29: 0 | BK29: 0 | BL29: notstarted | BM29: 51840 | BN29: 2025-04-02T14:00:26.219Z | BP29: 2012
A30: 2497092__79349 | B30: 2497092 | C30: 79349 | D30: 2537140 | E30: ABDELKARIM | G30: BELOUAFI | H30: 561968 | J30: 41573 | K30: 8.0 | L30: 2013-10-26T23:59:59.000Z | N30: CAN PADRO | O30: inperson | P30: 2013 | R30: selfpaced | S30: [567976, 567977] | U30: 79349 | V30: 2013-10-26T00:00:00.000Z | W30: active | X30: FALSO | Y30: 54627 | Z30: 51842 | AA30: 868 | AC30: 41573 | AD30: 0 | AE30: 2013 | AF30: 0 | AG30: 41573 | AH30: 0 | AI30: 54627 | AJ30: 51842 | AK30: 2529034 | AL30: FALSO | AM30: [] | AN30: 8 | AO30: 309418 | AP30: [] | AQ30: 0 | AR30: 0 | AS30: 2025-04-01T07:25:16.646Z | AU30: VERDADERO | AV30: CAN PADRO | AW30: FALSO | AX30: CONTRA INCENDIOS - CAN PADRO | BA30: active | BB30: FALSO | BC30: 0 | BD30: 0 | BE30: 0 | BF30: 0 | BG30: 2 | BH30: 868 | BI30: 0 | BJ30: 0 | BK30: 0 | BL30: notstarted | BM30: 51842 | BN30: 2025-04-02T14:00:26.537Z | BP30: 2004
A31: 2497093__79349 | B31: 2497093 | C31: 79349 | D31: 2537141 | E31: Fernando J | G31: Urbano Delgado | H31: 561969 | J31: 41573 | K31: 8.0 | L31: 2013-10-26T23:59:59.000Z | N31: CAN PADRO | O31: inperson | P31: 2013 | R31: selfpaced | S31: [567976, 567977] | U31: 79349 | V31: 2013-10-26T00:00:00.000Z | W31: active | X31: FALSO | Y31: 54627 | Z31: 51842 | AA31: 868 | AC31: 41573 | AD31: 0 | AE31: 2013 | AF31: 0 | AG31: 41573 | AH31: 0 | AI31: 54627 | AJ31: 51842 | AK31: 2529034 | AL31: FALSO | AM31: [] | AN31: 8 | AO31: 309418 | AP31: [] | AQ31: 0 | AR31: 0 | AS31: 2025-04-01T07:25:16.646Z | AU31: VERDADERO | AV31: CAN PADRO | AW31: FALSO | AX31: CONTRA INCENDIOS - CAN PADRO | BA31: active | BB31: FALSO | BC31: 0 | BD31: 0 | BE31: 0 | BF31: 0 | BG31: 2 | BH31: 868 | BI31: 0 | BJ31: 0 | BK31: 0 | BL31: notstarted | BM31: 51842 | BN31: 2025-04-02T14:00:26.537Z | BP31: 2004
A32: 2497090__79350 | B32: 2497090 | C32: 79350 | D32: 2537138 | E32: Immaculada | G32: Rodriguez Molino | H32: 561970 | J32: 41627 | K32: 16.0 | L32: 2013-12-19T23:59:59.000Z | N32: 3OR SOLUTIONS,S .L. | O32: inperson | P32: 2013 | R32: selfpaced | S32: [567978] | U32: 79350 | V32: 2013-12-18T00:00:00.000Z | W32: active | X32: FALSO | Y32: 54628 | Z32: 51843 | AA32: 625 | AC32: 41627 | AD32: 0 | AE32: 2013 | AF32: 0 | AG32: 41626 | AH32: 625 | AI32: 54628 | AJ32: 51843 | AK32: 2529034 | AL32: FALSO | AM32: [] | AN32: 343 | AO32: 309418 | AP32: [] | AQ32: 0 | AR32: 0 | AS32: 2025-04-01T07:25:16.913Z | AU32: VERDADERO | AV32: 3OR SOLUTIONS,S .L. | AW32: FALSO | AX32: FORMACIÓN CT+ | BA32: active | BB32: FALSO | BC32: 0 | BD32: 0 | BE32: 0 | BF32: 0 | BG32: 1 | BH32: 625 | BI32: 0 | BJ32: 0 | BK32: 625 | BL32: notstarted | BM32: 51843 | BN32: 2025-04-02T14:00:26.800Z | BP32: 2013
A33: 2497090__79351 | B33: 2497090 | C33: 79351 | D33: 2537138 | E33: Immaculada | G33: Rodriguez Molino | H33: 561971 | J33: 41431 | K33: 16.0 | L33: 2013-06-06T23:59:59.000Z | N33: IQS | O33: inperson | P33: 2013 | R33: selfpaced | S33: [567979] | U33: 79351 | V33: 2013-06-05T00:00:00.000Z | W33: active | X33: FALSO | Y33: 54629 | Z33: 51844 | AA33: 200 | AC33: 41431 | AD33: 0 | AE33: 2013 | AF33: 0 | AG33: 41430 | AH33: 200 | AI33: 54629 | AJ33: 51844 | AK33: 2529034 | AL33: FALSO | AM33: [] | AN33: 322 | AO33: 309418 | AP33: [] | AQ33: 0 | AR33: 0 | AS33: 2025-04-01T07:25:17.172Z | AU33: VERDADERO | AV33: IQS | AW33: FALSO | AX33: BIET'13 | BA33: active | BB33: FALSO | BC33: 0 | BD33: 0 | BE33: 0 | BF33: 0 | BG33: 1 | BH33: 200 | BI33: 0 | BJ33: 0 | BK33: 200 | BL33: notstarted | BM33: 51844 | BN33: 2025-04-02T14:00:27.067Z | BP33: 2013
A34: 2497090__79352 | B34: 2497090 | C34: 79352 | D34: 2537138 | E34: Immaculada | G34: Rodriguez Molino | H34: 561972 | J34: 41765 | K34: 6.0 | L34: 2014-05-06T23:59:59.000Z | N34: AIQS | O34: inperson | P34: 2014 | R34: selfpaced | S34: [567980] | U34: 79352 | V34: 2014-05-06T00:00:00.000Z | W34: active | X34: FALSO | Y34: 54630 | Z34: 51845 | AA34: 60 | AC34: 41765 | AD34: 0 | AE34: 2014 | AF34: 0 | AG34: 41765 | AH34: 60 | AI34: 54630 | AJ34: 51845 | AK34: 2529034 | AL34: FALSO | AM34: [] | AN34: 366 | AO34: 309418 | AP34: [] | AQ34: 0 | AR34: 0 | AS34: 2025-04-01T07:25:17.534Z | AU34: VERDADERO | AV34: AIQS | AW34: FALSO | AX34: CLEAN LABEL ALGO MÁS QUE UNA ETIQUETA LIMPIA | BA34: active | BB34: FALSO | BC34: 0 | BD34: 0 | BE34: 0 | BF34: 0 | BG34: 1 | BH34: 60 | BI34: 0 | BJ34: 0 | BK34: 60 | BL34: notstarted | BM34: 51845 | BN34: 2025-04-02T14:00:27.503Z | BP34: 2014
A35: 2497090__79353 | B35: 2497090 | C35: 79353 | D35: 2537138 | E35: Immaculada | G35: Rodriguez Molino | H35: 561973 | J35: 42159 | K35: 16.0 | L35: 2015-06-04T23:59:59.000Z | N35: A IQS | O35: inperson | P35: 2015 | R35: selfpaced | S35: [567981] | U35: 79353 | V35: 2015-06-03T00:00:00.000Z | W35: active | X35: FALSO | Y35: 54631 | Z35: 51848 | AA35: 175 | AC35: 42159 | AD35: 0 | AE35: 2015 | AF35: 0 | AG35: 42158 | AH35: 175 | AI35: 54631 | AJ35: 51848 | AK35: 2529034 | AL35: FALSO | AM35: [] | AN35: 401 | AO35: 309418 | AP35: [] | AQ35: 0 | AR35: 0 | AS35: 2025-04-01T07:25:18.414Z | AU35: VERDADERO | AV35: A IQS | AW35: FALSO | AX35: BIET/15 EUROPEAN MEETING ON BAKING INGREDIENTS, ENZYMES, AND TECHNOLOGY | BA35: active | BB35: FALSO | BC35: 0 | BD35: 0 | BE35: 0 | BF35: 0 | BG35: 1 | BH35: 175 | BI35: 0 | BJ35: 0 | BK35: 175 | BL35: notstarted | BM35: 51848 | BN35: 2025-04-02T14:00:27.950Z | BP35: 2015
A36: 2497090__79354 | B36: 2497090 | C36: 79354 | D36: 2537138 | E36: Immaculada | G36: Rodriguez Molino | H36: 561974 | J36: 42360 | K36: 8.0 | L36: 2015-12-22T23:59:59.000Z | N36: LA LLIMONA | O36: inperson | P36: 2015 | R36: selfpaced | S36: [567982] | U36: 79354 | V36: 2015-12-22T00:00:00.000Z | W36: active | X36: FALSO | Y36: 54632 | Z36: 51850 | AA36: 495 | AC36: 42360 | AD36: 0 | AE36: 2015 | AF36: 0 | AG36: 42360 | AH36: 495 | AI36: 54632 | AJ36: 51850 | AK36: 2529034 | AL36: FALSO | AM36: [] | AN36: 421 | AO36: 309418 | AP36: [] | AQ36: 0 | AR36: 0 | AS36: 2025-04-01T07:25:19.620Z | AU36: VERDADERO | AV36: LA LLIMONA | AW36: FALSO | AX36: FORMACIÓ EN NOU GESTOR DE CONTINGUTS PÀGINA WEB | BA36: active | BB36: FALSO | BC36: 0 | BD36: 0 | BE36: 0 | BF36: 0 | BG36: 1 | BH36: 495 | BI36: 0 | BJ36: 0 | BK36: 495 | BL36: notstarted | BM36: 51850 | BN36: 2025-04-02T14:00:28.258Z | BP36: 2015
A37: 2497094__79355 | B37: 2497094 | C37: 79355 | D37: 2537142 | E37: Carlos | G37: Rocamora Valls | H37: 561975 | J37: 42300 | K37: 1.0 | L37: 2015-10-23T23:59:59.000Z | N37: FORMACIÓN INTERNA: VERÒNICA GARCIA | O37: inperson | P37: 2015 | R37: selfpaced | S37: [567983] | U37: 79355 | V37: 2015-10-23T00:00:00.000Z | W37: active | X37: FALSO | Y37: 54633 | Z37: 51852 | AA37: 0 | AC37: 42300 | AD37: 0 | AE37: 2015 | AF37: 0 | AG37: 42300 | AH37: 0 | AI37: 54633 | AJ37: 51852 | AK37: 2529034 | AL37: FALSO | AM37: [] | AN37: 443 | AO37: 309418 | AP37: [] | AQ37: 0 | AR37: 0 | AS37: 2025-04-01T07:25:20.245Z | AU37: FALSO | AW37: FALSO | AX37: FORMACIÓN ACOGIDA: PREVENCIÓN DE RIESGOS, MEDIO AMBIENTE Y SEGURIDAD ALIMENTARIA | BA37: active | BB37: FALSO | BC37: 0 | BD37: 0 | BE37: 0 | BF37: 0 | BG37: 1 | BH37: 0 | BI37: 0 | BJ37: 0 | BK37: 0 | BL37: notstarted | BM37: 51852 | BN37: 2025-04-02T14:00:28.531Z | BP37: 2015
A38: 2497090__79356 | B38: 2497090 | C38: 79356 | D38: 2537138 | E38: Immaculada | G38: Rodriguez Molino | H38: 561976 | J38: 42691 | K38: 7.0 | L38: 2016-11-17T23:59:59.000Z | N38: SILLIKER IBÉRICA S.A.U. | O38: inperson | P38: 2016 | R38: selfpaced | S38: [567984] | U38: 79356 | V38: 2016-11-17T00:00:00.000Z | W38: active | X38: FALSO | Y38: 54634 | Z38: 51853 | AA38: 904 | AC38: 42691 | AD38: 0 | AE38: 2016 | AF38: 0 | AG38: 42691 | AH38: 0 | AI38: 54634 | AJ38: 51853 | AK38: 2529034 | AL38: FALSO | AM38: [] | AN38: 455 | AO38: 309418 | AP38: [] | AQ38: 0 | AR38: 0 | AS38: 2025-04-01T07:25:20.507Z | AU38: VERDADERO | AV38: SILLIKER IBÉRICA S.A.U. | AW38: FALSO | AX38: LEGISLACIÓN ALIMENTARIA | BA38: active | BB38: FALSO | BC38: 0 | BD38: 0 | BE38: 0 | BF38: 0 | BG38: 1 | BH38: 904 | BI38: 0 | BJ38: 0 | BK38: 0 | BL38: notstarted | BM38: 51853 | BN38: 2025-04-02T14:00:28.808Z | BP38: 2016
A39: 2497090__79357 | B39: 2497090 | C39: 79357 | D39: 2537138 | E39: Immaculada | G39: Rodriguez Molino | H39: 561977 | J39: 42719 | K39: 2.0 | L39: 2016-12-15T23:59:59.000Z | N39: Intern: JOSÉ RAMOS | O39: inperson | P39: 2016 | R39: selfpaced | S39: [567985, 567986, 567987, 567988, 567989] | U39: 79357 | V39: 2016-12-15T00:00:00.000Z | W39: active | X39: FALSO | Y39: 54635 | Z39: 51855 | AA39: 0 | AC39: 42719 | AD39: 0 | AE39: 2016 | AF39: 0 | AG39: 42719 | AH39: 0 | AI39: 54635 | AJ39: 51855 | AK39: 2529034 | AL39: FALSO | AM39: [] | AN39: 51 | AO39: 309418 | AP39: [] | AQ39: 0 | AR39: 0 | AS39: 2025-04-01T07:25:21.048Z | AU39: FALSO | AW39: FALSO | AX39: PREVENCION DEL RIESGO MANIPULACION PRODUCTOS QUIMICOS PELIGROSOS | BA39: active | BB39: FALSO | BC39: 0 | BD39: 0 | BE39: 0 | BF39: 0 | BG39: 5 | BH39: 0 | BI39: 0 | BJ39: 0 | BK39: 0 | BL39: notstarted | BM39: 51855 | BN39: 2025-04-02T14:00:29.101Z | BP39: 2016
A40: 2497092__79357 | B40: 2497092 | C40: 79357 | D40: 2537140 | E40: ABDELKARIM | G40: BELOUAFI | H40: 561978 | J40: 42719 | K40: 2.0 | L40: 2016-12-15T23:59:59.000Z | N40: Intern: JOSÉ RAMOS | O40: inperson | P40: 2016 | R40: selfpaced | S40: [567985, 567986, 567987, 567988, 567989] | U40: 79357 | V40: 2016-12-15T00:00:00.000Z | W40: active | X40: FALSO | Y40: 54635 | Z40: 51855 | AA40: 0 | AC40: 42719 | AD40: 0 | AE40: 2016 | AF40: 0 | AG40: 42719 | AH40: 0 | AI40: 54635 | AJ40: 51855 | AK40: 2529034 | AL40: FALSO | AM40: [] | AN40: 51 | AO40: 309418 | AP40: [] | AQ40: 0 | AR40: 0 | AS40: 2025-04-01T07:25:21.048Z | AU40: FALSO | AW40: FALSO | AX40: PREVENCION DEL RIESGO MANIPULACION PRODUCTOS QUIMICOS PELIGROSOS | BA40: active | BB40: FALSO | BC40: 0 | BD40: 0 | BE40: 0 | BF40: 0 | BG40: 5 | BH40: 0 | BI40: 0 | BJ40: 0 | BK40: 0 | BL40: notstarted | BM40: 51855 | BN40: 2025-04-02T14:00:29.101Z | BP40: 2016
A41: 2497093__79357 | B41: 2497093 | C41: 79357 | D41: 2537141 | E41: Fernando J | G41: Urbano Delgado | H41: 561979 | J41: 42719 | K41: 2.0 | L41: 2016-12-15T23:59:59.000Z | N41: Intern: JOSÉ RAMOS | O41: inperson | P41: 2016 | R41: selfpaced | S41: [567985, 567986, 567987, 567988, 567989] | U41: 79357 | V41: 2016-12-15T00:00:00.000Z | W41: active | X41: FALSO | Y41: 54635 | Z41: 51855 | AA41: 0 | AC41: 42719 | AD41: 0 | AE41: 2016 | AF41: 0 | AG41: 42719 | AH41: 0 | AI41: 54635 | AJ41: 51855 | AK41: 2529034 | AL41: FALSO | AM41: [] | AN41: 51 | AO41: 309418 | AP41: [] | AQ41: 0 | AR41: 0 | AS41: 2025-04-01T07:25:21.048Z | AU41: FALSO | AW41: FALSO | AX41: PREVENCION DEL RIESGO MANIPULACION PRODUCTOS QUIMICOS PELIGROSOS | BA41: active | BB41: FALSO | BC41: 0 | BD41: 0 | BE41: 0 | BF41: 0 | BG41: 5 | BH41: 0 | BI41: 0 | BJ41: 0 | BK41: 0 | BL41: notstarted | BM41: 51855 | BN41: 2025-04-02T14:00:29.101Z | BP41: 2016
A42: 2497094__79357 | B42: 2497094 | C42: 79357 | D42: 2537142 | E42: Carlos | G42: Rocamora Valls | H42: 561980 | J42: 42719 | K42: 2.0 | L42: 2016-12-15T23:59:59.000Z | N42: Intern: JOSÉ RAMOS | O42: inperson | P42: 2016 | R42: selfpaced | S42: [567985, 567986, 567987, 567988, 567989] | U42: 79357 | V42: 2016-12-15T00:00:00.000Z | W42: active | X42: FALSO | Y42: 54635 | Z42: 51855 | AA42: 0 | AC42: 42719 | AD42: 0 | AE42: 2016 | AF42: 0 | AG42: 42719 | AH42: 0 | AI42: 54635 | AJ42: 51855 | AK42: 2529034 | AL42: FALSO | AM42: [] | AN42: 51 | AO42: 309418 | AP42: [] | AQ42: 0 | AR42: 0 | AS42: 2025-04-01T07:25:21.048Z | AU42: FALSO | AW42: FALSO | AX42: PREVENCION DEL RIESGO MANIPULACION PRODUCTOS QUIMICOS PELIGROSOS | BA42: active | BB42: FALSO | BC42: 0 | BD42: 0 | BE42: 0 | BF42: 0 | BG42: 5 | BH42: 0 | BI42: 0 | BJ42: 0 | BK42: 0 | BL42: notstarted | BM42: 51855 | BN42: 2025-04-02T14:00:29.101Z | BP42: 2016
A43: 2497095__79357 | B43: 2497095 | C43: 79357 | D43: 2537143 | E43: Francisco | G43: Martin Sabariego | H43: 561981 | J43: 42719 | K43: 2.0 | L43: 2016-12-15T23:59:59.000Z | N43: Intern: JOSÉ RAMOS | O43: inperson | P43: 2016 | R43: selfpaced | S43: [567985, 567986, 567987, 567988, 567989] | U43: 79357 | V43: 2016-12-15T00:00:00.000Z | W43: active | X43: FALSO | Y43: 54635 | Z43: 51855 | AA43: 0 | AC43: 42719 | AD43: 0 | AE43: 2016 | AF43: 0 | AG43: 42719 | AH43: 0 | AI43: 54635 | AJ43: 51855 | AK43: 2529034 | AL43: FALSO | AM43: [] | AN43: 51 | AO43: 309418 | AP43: [] | AQ43: 0 | AR43: 0 | AS43: 2025-04-01T07:25:21.048Z | AU43: FALSO | AW43: FALSO | AX43: PREVENCION DEL RIESGO MANIPULACION PRODUCTOS QUIMICOS PELIGROSOS | BA43: active | BB43: FALSO | BC43: 0 | BD43: 0 | BE43: 0 | BF43: 0 | BG43: 5 | BH43: 0 | BI43: 0 | BJ43: 0 | BK43: 0 | BL43: notstarted | BM43: 51855 | BN43: 2025-04-02T14:00:29.101Z | BP43: 2016
A44: 2497090__79358 | B44: 2497090 | C44: 79358 | D44: 2537138 | E44: Immaculada | G44: Rodriguez Molino | H44: 561982 | J44: 42894 | K44: 9.0 | L44: 2017-06-08T23:59:59.000Z | N44: IQS | O44: inperson | P44: 2017 | R44: selfpaced | S44: [567990, 567991] | U44: 79358 | V44: 2017-06-07T00:00:00.000Z | W44: active | X44: FALSO | Y44: 54636 | Z44: 51856 | AA44: 500 | AC44: 42894 | AD44: 0 | AE44: 2017 | AF44: 0 | AG44: 42893 | AH44: 0 | AI44: 54636 | AJ44: 51856 | AK44: 2529034 | AL44: FALSO | AM44: [] | AN44: 499 | AO44: 309418 | AP44: [] | AQ44: 0 | AR44: 0 | AS44: 2025-04-01T07:25:21.327Z | AU44: VERDADERO | AV44: IQS | AW44: FALSO | AX44: BIET'17 | BA44: active | BB44: FALSO | BC44: 0 | BD44: 0 | BE44: 0 | BF44: 0 | BG44: 2 | BH44: 500 | BI44: 0 | BJ44: 0 | BK44: 0 | BL44: notstarted | BM44: 51856 | BN44: 2025-04-02T14:00:29.383Z | BP44: 2017
A45: 2497094__79358 | B45: 2497094 | C45: 79358 | D45: 2537142 | E45: Carlos | G45: Rocamora Valls | H45: 561983 | J45: 42894 | K45: 9.0 | L45: 2017-06-08T23:59:59.000Z | N45: IQS | O45: inperson | P45: 2017 | R45: selfpaced | S45: [567990, 567991] | U45: 79358 | V45: 2017-06-07T00:00:00.000Z | W45: active | X45: FALSO | Y45: 54636 | Z45: 51856 | AA45: 500 | AC45: 42894 | AD45: 0 | AE45: 2017 | AF45: 0 | AG45: 42893 | AH45: 0 | AI45: 54636 | AJ45: 51856 | AK45: 2529034 | AL45: FALSO | AM45: [] | AN45: 499 | AO45: 309418 | AP45: [] | AQ45: 0 | AR45: 0 | AS45: 2025-04-01T07:25:21.327Z | AU45: VERDADERO | AV45: IQS | AW45: FALSO | AX45: BIET'17 | BA45: active | BB45: FALSO | BC45: 0 | BD45: 0 | BE45: 0 | BF45: 0 | BG45: 2 | BH45: 500 | BI45: 0 | BJ45: 0 | BK45: 0 | BL45: notstarted | BM45: 51856 | BN45: 2025-04-02T14:00:29.383Z | BP45: 2017
A46: 2497090__79359 | B46: 2497090 | C46: 79359 | D46: 2537138 | E46: Immaculada | G46: Rodriguez Molino | H46: 561984 | J46: 43005 | K46: 7.0 | L46: 2017-09-27T23:59:59.000Z | N46: SILLIKER IBÉRICA S.A.U. | O46: inperson | P46: 2017 | R46: selfpaced | S46: [567992] | U46: 79359 | V46: 2017-09-27T00:00:00.000Z | W46: active | X46: FALSO | Y46: 54637 | Z46: 51857 | AA46: 455 | AC46: 43005 | AD46: 0 | AE46: 2017 | AF46: 0 | AG46: 43005 | AH46: 455 | AI46: 54637 | AJ46: 51857 | AK46: 2529034 | AL46: FALSO | AM46: [] | AN46: 500 | AO46: 309418 | AP46: [] | AQ46: 0 | AR46: 0 | AS46: 2025-04-01T07:25:21.706Z | AU46: VERDADERO | AV46: SILLIKER IBÉRICA S.A.U. | AW46: FALSO | AX46: FOOD DEFENSE | BA46: active | BB46: FALSO | BC46: 0 | BD46: 0 | BE46: 0 | BF46: 0 | BG46: 1 | BH46: 455 | BI46: 0 | BJ46: 0 | BK46: 455 | BL46: notstarted | BM46: 51857 | BN46: 2025-04-02T14:00:29.695Z | BP46: 2017
A47: 2497090__79360 | B47: 2497090 | C47: 79360 | D47: 2537138 | E47: Immaculada | G47: Rodriguez Molino | H47: 561985 | J47: 43034 | K47: 4.0 | L47: 2017-10-26T23:59:59.000Z | N47: SILLIKER IBÉRICA, S.A.U. | O47: inperson | P47: 2017 | R47: selfpaced | S47: [567993, 567994] | U47: 79360 | V47: 2017-10-26T00:00:00.000Z | W47: active | X47: FALSO | Y47: 54638 | Z47: 51858 | AA47: 450 | AC47: 43034 | AD47: 0 | AE47: 2017 | AF47: 0 | AG47: 43034 | AH47: 450 | AI47: 54638 | AJ47: 51858 | AK47: 2529034 | AL47: FALSO | AM47: [] | AN47: 346 | AO47: 309418 | AP47: [] | AQ47: 0 | AR47: 0 | AS47: 2025-04-01T07:25:22.016Z | AU47: VERDADERO | AV47: SILLIKER IBÉRICA, S.A.U. | AW47: FALSO | AX47: FORMACIO APPCC | BA47: active | BB47: FALSO | BC47: 0 | BD47: 0 | BE47: 0 | BF47: 0 | BG47: 2 | BH47: 450 | BI47: 0 | BJ47: 0 | BK47: 450 | BL47: notstarted | BM47: 51858 | BN47: 2025-04-02T14:00:30.039Z | BP47: 2013
A48: 2497093__79360 | B48: 2497093 | C48: 79360 | D48: 2537141 | E48: Fernando J | G48: Urbano Delgado | H48: 561986 | J48: 43034 | K48: 4.0 | L48: 2017-10-26T23:59:59.000Z | N48: SILLIKER IBÉRICA, S.A.U. | O48: inperson | P48: 2017 | R48: selfpaced | S48: [567993, 567994] | U48: 79360 | V48: 2017-10-26T00:00:00.000Z | W48: active | X48: FALSO | Y48: 54638 | Z48: 51858 | AA48: 450 | AC48: 43034 | AD48: 0 | AE48: 2017 | AF48: 0 | AG48: 43034 | AH48: 450 | AI48: 54638 | AJ48: 51858 | AK48: 2529034 | AL48: FALSO | AM48: [] | AN48: 346 | AO48: 309418 | AP48: [] | AQ48: 0 | AR48: 0 | AS48: 2025-04-01T07:25:22.016Z | AU48: VERDADERO | AV48: SILLIKER IBÉRICA, S.A.U. | AW48: FALSO | AX48: FORMACIO APPCC | BA48: active | BB48: FALSO | BC48: 0 | BD48: 0 | BE48: 0 | BF48: 0 | BG48: 2 | BH48: 450 | BI48: 0 | BJ48: 0 | BK48: 450 | BL48: notstarted | BM48: 51858 | BN48: 2025-04-02T14:00:30.039Z | BP48: 2013
...

Sheet Participantes_norm
A1: participantes_session_access_membership_id | B1: participantes_access_id | C1: employee_id | D1: session_id | E1: participantes_first_name | F1: participantes_last_name | G1: participantes_job_title
A2: 561940 | B2: 2537138 | C2: 2497090 | D2: 79325 | E2: Immaculada | F2: Rodriguez Molino
A3: 561941 | B3: 2537138 | C3: 2497090 | D3: 79326 | E3: Immaculada | F3: Rodriguez Molino
A4: 561942 | B4: 2537138 | C4: 2497090 | D4: 79327 | E4: Immaculada | F4: Rodriguez Molino
A5: 561943 | B5: 2537138 | C5: 2497090 | D5: 79328 | E5: Immaculada | F5: Rodriguez Molino
A6: 561944 | B6: 2537138 | C6: 2497090 | D6: 79329 | E6: Immaculada | F6: Rodriguez Molino
A7: 561945 | B7: 2537140 | C7: 2497092 | D7: 79330 | E7: ABDELKARIM | F7: BELOUAFI
A8: 561946 | B8: 2537143 | C8: 2497095 | D8: 79330 | E8: Francisco | F8: Martin Sabariego
A9: 561947 | B9: 2537144 | C9: 2497096 | D9: 79330 | E9: Queralt | F9: Pich Oliveras
A10: 561948 | B10: 2537138 | C10: 2497090 | D10: 79331 | E10: Immaculada | F10: Rodriguez Molino
A11: 561949 | B11: 2537138 | C11: 2497090 | D11: 79332 | E11: Immaculada | F11: Rodriguez Molino
A12: 561950 | B12: 2537138 | C12: 2497090 | D12: 79333 | E12: Immaculada | F12: Rodriguez Molino
A13: 561951 | B13: 2537140 | C13: 2497092 | D13: 79334 | E13: ABDELKARIM | F13: BELOUAFI
... A90: 610513 | B90: 2537138 | C90: 2497090 | D90: 84851 | E90: Immaculada | F90: Rodriguez Molino

Sheet Sesiones_norm
A1: sesiones_session_id | B1: sesiones_name | C1: sesiones_training_id | D1: sesiones_description | E1: sesiones_training_class_id | F1: sesiones_starts_at | G1: sesiones_ends_at | H1: sesiones_due_date | I1: sesiones_duration | J1: sesiones_modality | K1: sesiones_schedule | L1: sesiones_link | M1: sesiones_location | N1: sesiones_session_attendance_ids | O1: sesiones_session_feedback_id | P1: sesiones_subsidized | Q1: sesiones_status | R1: sesiones_parent_id
A2: 79325 | B2: 2004 | C2: 51803 | E2: 54603 | F2: 2004-09-13T00:00:00.000Z | G2: 2004-09-15T23:59:59.000Z | H2: 38245 | I2: 1.0 | J2: inperson | K2: selfpaced | M2: FORMACION INTERNA | N2: [567948] | P2: FALSO | Q2: active
A3: 79326 | B3: 2005 | C3: 51808 | E3: 54604 | F3: 2005-10-17T00:00:00.000Z | G3: 2006-06-30T23:59:59.000Z | H3: 38898 | I3: 0.07 | J3: inperson | K3: selfpaced | M3: CIEF | N3: [567949] | P3: FALSO | Q3: active
A4: 79327 | B4: 2006 | C4: 51808 | E4: 54605 | F4: 2006-01-11T00:00:00.000Z | G4: 2006-12-20T23:59:59.000Z | H4: 39071 | I4: 4.0 | J4: inperson | K4: selfpaced | M4: CIEF | N4: [567950] | P4: FALSO | Q4: active
A5: 79328 | B5: 2005 | C5: 51810 | E5: 54606 | F5: 2005-05-23T00:00:00.000Z | G5: 2005-05-25T23:59:59.000Z | H5: 38497 | I5: 20.0 | J5: inperson | K5: selfpaced | M5: AULA BDN, SCP | N5: [567951] | P5: FALSO | Q5: active
A6: 79329 | B6: 2007 | C6: 51811 | E6: 54607 | F6: 2007-11-12T00:00:00.000Z | G6: 2007-11-12T23:59:59.000Z | H6: 39398 | I6: 2.0 | J6: inperson | K6: selfpaced | M6: MEGARA SOCIEDAD DE PREVENCIÓN DE MUTUA E | N6: [567952] | P6: FALSO | Q6: active
A7: 79330 | B7: 2021 | C7: 51811 | E7: 54608 | F7: 2021-03-11T00:00:00.000Z | G7: 2021-03-11T23:59:59.000Z | H7: 44266 | I7: 3.0 | J7: inperson | K7: selfpaced | M7: GRUPO PREVING | N7: [567953, 567954, 567955] | P7: FALSO | Q7: active
A8: 79331 | B8: 2007 | C8: 51812 | E8: 54609 | F8: 2007-11-22T00:00:00.000Z | G8: 2007-11-22T23:59:59.000Z | H8: 39408 | I8: 8.0 | J8: inperson | K8: selfpaced | M8: ASOCIACIÓN DE QUÍMICOS E INGENIEROS | N8: [567956] | P8: FALSO | Q8: active
A9: 79332 | B9: 2007 | C9: 51813 | E9: 54610 | F9: 2007-03-23T00:00:00.000Z | G9: 2007-03-23T23:59:59.000Z | H9: 39164 | I9: 0.0 | J9: inperson | K9: selfpaced | M9: AGÈNCIA CATALANA DE SEGUETAT ALIMENTARIA | N9: [567957] | P9: FALSO | Q9: active
A10: 79333 | B10: 2008 | C10: 51814 | E10: 54611 | F10: 2008-10-27T00:00:00.000Z | G10: 2008-10-27T23:59:59.000Z | H10: 39748 | I10: 4.0 | J10: inperson | K10: selfpaced | M10: EGARSAT | N10: [567958] | P10: FALSO | Q10: active
A11: 79334 | B11: 2008 | C11: 51816 | E11: 54612 | F11: 2008-11-18T00:00:00.000Z | G11: 2008-11-18T23:59:59.000Z | H11: 39770 | I11: 2.0 | J11: inperson | K11: selfpaced | M11: EGARSAT | N11: [567959, 567960] | P11: FALSO | Q11: active
A12: 79335 | B12: 2008 | C12: 51817 | E12: 54613 | F12: 2008-11-18T00:00:00.000Z | G12: 2008-11-18T23:59:59.000Z | H12: 39770 | I12: 2.0 | J12: inperson | K12: selfpaced | M12: EGARSAT | N12: [567961, 567962] | P12: FALSO | Q12: active
A13: 79336 | B13: 2008 | C13: 51819 | E13: 54614 | F13: 2008-03-26T00:00:00.000Z | G13: 2008-03-27T23:59:59.000Z | H13: 39534 | I13: 12.0 | J13: inperson | K13: selfpaced | M13: ASOCIACIÓN DE FABRICANTES Y COMERCIALIZA | N13: [567963] | P13: FALSO | Q13: active
... A19: 79342 | B19: 2016 | C19: 51827 | E19: 54620 | F19: 2016-10-19T00:00:00.000Z | G19: 2016-10-20T23:59:59.000Z | H19: 42663 | I19: 13.0 | J19: inperson | K19: selfpaced | M19: ASOCIACIÓN ESPAÑOLA DE TÉCNICOS CEREALIS | N19: [567969] | P19: FALSO | Q19: active
A20: 79343 | B20: 2011 I | C20: 51830 | E20: 54621 | F20: 2011-05-04T00:00:00.000Z | G20: 2011-05-04T23:59:59.000Z | H20: 40667 | I20: 2.0 | J20: inperson | K20: selfpaced | M20: EGARSAT | N20: [567970] | P20: FALSO | Q20: active
A21: 79344 | B21: 2011 II | C21: 51830 | E21: 54622 | F21: 2011-05-18T00:00:00.000Z | G21: 2011-05-18T23:59:59.000Z | H21: 40681 | I21: 2.0 | J21: inperson | K21: selfpaced | M21: EGARSAT | N21: [567971] | P21: FALSO | Q21: active
A22: 79345 | B22: 2011 I | C22: 51831 | E22: 54623 | F22: 2011-05-04T00:00:00.000Z | G22: 2011-05-04T23:59:59.000Z | H22: 40667 | I22: 2.0 | J22: inperson | K22: selfpaced | M22: EGARSAT | N22: [567972] | P22: FALSO | Q22: active
A23: 79346 | B23: 2011 II | C23: 51831 | E23: 54624 | F23: 2011-05-18T00:00:00.000Z | G23: 2011-05-18T23:59:59.000Z | H23: 40681 | I23: 2.0 | J23: inperson | K23: selfpaced | M23: EGARSAT | N23: [567973] | P23: FALSO | Q23: active
A24: 79347 | B24: 2012 | C24: 51832 | E24: 54625 | F24: 2012-09-26T00:00:00.000Z | G24: 2012-09-26T23:59:59.000Z | H24: 41178 | I24: 1.0 | J24: inperson | K24: selfpaced | M24: EGARSAT | N24: [567974] | P24: FALSO | Q24: active
A25: 79348 | B25: 2012 | C25: 51840 | E25: 54626 | F25: 2012-09-26T00:00:00.000Z | G25: 2012-09-26T23:59:59.000Z | H25: 41178 | I25: 1.0 | J25: inperson | K25: selfpaced | M25: EGARSAT | N25: [567975] | P25: FALSO | Q25: active
A26: 79349 | B26: 2013 | C26: 51842 | E26: 54627 | F26: 2013-10-26T00:00:00.000Z | G26: 2013-10-26T23:59:59.000Z | H26: 41573 | I26: 8.0 | J26: inperson | K26: selfpaced | M26: CAN PADRO | N26: [567976, 567977] | P26: FALSO | Q26: active
A27: 79350 | B27: 2013 | C27: 51843 | E27: 54628 | F27: 2013-12-18T00:00:00.000Z | G27: 2013-12-19T23:59:59.000Z | H27: 41627 | I27: 16.0 | J27: inperson | K27: selfpaced | M27: 3OR SOLUTIONS,S .L. | N27: [567978] | P27: FALSO | Q27: active
A28: 79351 | B28: 2013 | C28: 51844 | E28: 54629 | F28: 2013-06-05T00:00:00.000Z | G28: 2013-06-06T23:59:59.000Z | H28: 41431 | I28: 16.0 | J28: inperson | K28: selfpaced | M28: IQS | N28: [567979] | P28: FALSO | Q28: active
A29: 79352 | B29: 2014 | C29: 51845 | E29: 54630 | F29: 2014-05-06T00:00:00.000Z | G29: 2014-05-06T23:59:59.000Z | H29: 41765 | I29: 6.0 | J29: inperson | K29: selfpaced | M29: AIQS | N29: [567980] | P29: FALSO | Q29: active
A30: 79353 | B30: 2015 | C30: 51848 | E30: 54631 | F30: 2015-06-03T00:00:00.000Z | G30: 2015-06-04T23:59:59.000Z | H30: 42159 | I30: 16.0 | J30: inperson | K30: selfpaced | M30: A IQS | N30: [567981] | P30: FALSO | Q30: active
A31: 79354 | B31: 2015 | C31: 51850 | E31: 54632 | F31: 2015-12-22T00:00:00.000Z | G31: 2015-12-22T23:59:59.000Z | H31: 42360 | I31: 8.0 | J31: inperson | K31: selfpaced | M31: LA LLIMONA | N31: [567982] | P31: FALSO | Q31: active
A32: 79355 | B32: 2015 | C32: 51852 | E32: 54633 | F32: 2015-10-23T00:00:00.000Z | G32: 2015-10-23T23:59:59.000Z | H32: 42300 | I32: 1.0 | J32: inperson | K32: selfpaced | M32: FORMACIÓN INTERNA: VERÒNICA GARCIA | N32: [567983] | P32: FALSO | Q32: active
A33: 79356 | B33: 2016 | C33: 51853 | E33: 54634 | F33: 2016-11-17T00:00:00.000Z | G33: 2016-11-17T23:59:59.000Z | H33: 42691 | I33: 7.0 | J33: inperson | K33: selfpaced | M33: SILLIKER IBÉRICA S.A.U. | N33: [567984] | P33: FALSO | Q33: active
A34: 79357 | B34: 2016 | C34: 51855 | E34: 54635 | F34: 2016-12-15T00:00:00.000Z | G34: 2016-12-15T23:59:59.000Z | H34: 42719 | I34: 2.0 | J34: inperson | K34: selfpaced | M34: Intern: JOSÉ RAMOS | N34: [567985, 567986, 567987, 567988, 567989] | P34: FALSO | Q34: active
A35: 79358 | B35: 2017 | C35: 51856 | E35: 54636 | F35: 2017-06-07T00:00:00.000Z | G35: 2017-06-08T23:59:59.000Z | H35: 42894 | I35: 9.0 | J35: inperson | K35: selfpaced | M35: IQS | N35: [567990, 567991] | P35: FALSO | Q35: active
... A43: 79366 | B43: 2019 | C43: 51864 | E43: 54644 | F43: 2019-10-03T00:00:00.000Z | G43: 2019-10-03T23:59:59.000Z | H43: 43741 | I43: 1.0 | J43: inperson | K43: selfpaced | M43: SILLIKER IBERICA | N43: [568000] | P43: FALSO | Q43: active
A44: 79367 | B44: 2019 | C44: 51865 | E44: 54645 | F44: 2019-09-30T00:00:00.000Z | G44: 2019-09-30T23:59:59.000Z | H44: 43738 | I44: 45781 | J44: inperson | K44: selfpaced | M44: PRODECA - PROMOTORA DELS ALIMENTS CATALA | N44: [568001] | P44: FALSO | Q44: active
A45: 79368 | B45: 2020 | C45: 51866 | E45: 54646 | F45: 2020-01-31T00:00:00.000Z | G45: 2020-01-31T23:59:59.000Z | H45: 43861 | I45: 1.0 | J45: inperson | K45: selfpaced | M45: EGARSAT - JOSE MIGUEL ORDAS TERRONES | N45: [568002, 568003, 568004] | P45: FALSO | Q45: active
A46: 79369 | B46: 2020 | C46: 51867 | E46: 54647 | F46: 2020-02-19T00:00:00.000Z | G46: 2020-02-19T23:59:59.000Z | H46: 43880 | I46: 5.0 | J46: inperson | K46: selfpaced | M46: SILLIKER IBÉRICA S.A.U. | N46: [568005, 568006] | P46: FALSO | Q46: active
A47: 79370 | B47: 2021 | C47: 51868 | E47: 54648 | F47: 2021-03-09T00:00:00.000Z | G47: 2021-03-09T23:59:59.000Z | H47: 44264 | I47: 3.0 | J47: inperson | K47: selfpaced | M47: GRUPO PREVING | N47: [568007, 568008, 568009] | P47: FALSO | Q47: active
A48: 79371 | B48: 2021 | C48: 51869 | E48: 54649 | F48: 2021-03-16T00:00:00.000Z | G48: 2021-03-16T23:59:59.000Z | H48: 44271 | I48: 3.0 | J48: inperson | K48: selfpaced | M48: GRUPO PREVING | N48: [568010, 568011, 568012] | P48: FALSO | Q48: active
A49: 79372 | B49: 2021 | C49: 51870 | E49: 54650 | F49: 2021-03-09T00:00:00.000Z | G49: 2021-03-09T23:59:59.000Z | H49: 44264 | I49: 3.0 | J49: inperson | K49: selfpaced | M49: GRUPO PREVING | N49: [568013, 568014, 568015] | P49: FALSO | Q49: active
A50: 79373 | B50: 2021 | C50: 51871 | E50: 54651 | F50: 2021-03-11T00:00:00.000Z | G50: 2021-03-11T23:59:59.000Z | H50: 44266 | I50: 3.0 | J50: inperson | K50: selfpaced | M50: GRUPO PREVING | N50: [568016, 568017, 568018, 568019] | P50: FALSO | Q50: active
A51: 79374 | B51: 2021 | C51: 51873 | E51: 54652 | F51: 2021-10-27T00:00:00.000Z | G51: 2021-10-27T23:59:59.000Z | H51: 44496 | I51: 4.0 | J51: inperson | K51: selfpaced | M51: PREVENCIÓ I SALUT DEL BAGES SL | N51: [568020] | P51: 0 | Q51: active
A52: 79375 | B52: 2021 | C52: 51874 | E52: 54653 | F52: 2021-10-15T00:00:00.000Z | G52: 2021-10-15T23:59:59.000Z | H52: 44484 | I52: 45778 | J52: inperson | K52: selfpaced | M52: CONSELL CATALÀ DE RESUSCITACIÓ | N52: [568021] | P52: 0 | Q52: active
...

Sheet Grupos_norm
A1: grupos_training_class_id | B1: grupos_training_id | C1: curse_code | D1: grupos_name | E1: grupos_description | F1: grupos_start_date | G1: grupos_end_date | H1: grupos_cost | I1: grupos_indirect_cost | J1: grupos_salary_cost | K1: grupos_subsidized_cost
A2: 54603 | B2: 51803 | C2: {=XLOOKUP(B2,Cursos_norm!$A$2:$A$85,Cursos_norm!$E$2:$E$85)} -> 9 | D2: 2004 | F2: 38243 | G2: 38245 | H2: 0 | I2: 0 | J2: 0 | K2: 0
A3: 54604 | B3: 51808 | C3: {=XLOOKUP(B3,Cursos_norm!$A$2:$A$85,Cursos_norm!$E$2:$E$85)} -> 15 | D3: 2005 | F3: 38642 | G3: 38898 | H3: 0 | I3: 0 | J3: 0 | K3: 0
A4: 54605 | B4: 51808 | C4: {=XLOOKUP(B4,Cursos_norm!$A$2:$A$85,Cursos_norm!$E$2:$E$85)} -> 15 | D4: 2006 | F4: 38728 | G4: 39071 | H4: 0 | I4: 0 | J4: 0 | K4: 0
A5: 54606 | B5: 51810 | C5: {=XLOOKUP(B5,Cursos_norm!$A$2:$A$85,Cursos_norm!$E$2:$E$85)} -> 32 | D5: 2005 | F5: 38495 | G5: 38497 | H5: 248 | I5: 0 | J5: 0 | K5: 0
A6: 54607 | B6: 51811 | C6: {=XLOOKUP(B6,Cursos_norm!$A$2:$A$85,Cursos_norm!$E$2:$E$85)} -> 105 | D6: 2007 | F6: 39398 | G6: 39398 | H6: 0 | I6: 0 | J6: 0 | K6: 0
A7: 54608 | B7: 51811 | C7: {=XLOOKUP(B7,Cursos_norm!$A$2:$A$85,Cursos_norm!$E$2:$E$85)} -> 105 | D7: 2021 | F7: 44266 | G7: 44266 | H7: 0 | I7: 0 | J7: 0 | K7: 0
A8: 54609 | B8: 51812 | C8: {=XLOOKUP(B8,Cursos_norm!$A$2:$A$85,Cursos_norm!$E$2:$E$85)} -> 100 | D8: 2007 | F8: 39408 | G8: 39408 | H8: 150 | I8: 0 | J8: 0 | K8: 150
A9: 54610 | B9: 51813 | C9: {=XLOOKUP(B9,Cursos_norm!$A$2:$A$85,Cursos_norm!$E$2:$E$85)} -> 92 | D9: 2007 | F9: 39164 | G9: 39164 | H9: 0 | I9: 0 | J9: 0 | K9: 0
A10: 54611 | B10: 51814 | C10: {=XLOOKUP(B10,Cursos_norm!$A$2:$A$85,Cursos_norm!$E$2:$E$85)} -> 159 | D10: 2008 | F10: 39748 | G10: 39748 | H10: 0 | I10: 0 | J10: 0 | K10: 0
A11: 54612 | B11: 51816 | C11: {=XLOOKUP(B11,Cursos_norm!$A$2:$A$85,Cursos_norm!$E$2:$E$85)} -> 185 | D11: 2008 | F11: 39770 | G11: 39770 | H11: 0 | I11: 0 | J11: 0 | K11: 0
A12: 54613 | B12: 51817 | C12: {=XLOOKUP(B12,Cursos_norm!$A$2:$A$85,Cursos_norm!$E$2:$E$85)} -> 166 | D12: 2008 | F12: 39770 | G12: 39770 | H12: 0 | I12: 0 | J12: 0 | K12: 0
A13: 54614 | B13: 51819 | C13: {=XLOOKUP(B13,Cursos_norm!$A$2:$A$85,Cursos_norm!$E$2:$E$85)} -> 134 | D13: 2008 | F13: 39533 | G13: 39534 | H13: 45 | I13: 0 | J13: 0 | K13: 45
... A19: 54620 | B19: 51827 | C19: {=XLOOKUP(B19,Cursos_norm!$A$2:$A$85,Cursos_norm!$E$2:$E$85)} -> 250 | D19: 2016 | F19: 42662 | G19: 42663 | H19: 350 | I19: 0 | J19: 0 | K19: 0
A20: 54621 | B20: 51830 | C20: {=XLOOKUP(B20,Cursos_norm!$A$2:$A$85,Cursos_norm!$E$2:$E$85)} -> 221 | D20: 2011 I | F20: 40667 | G20: 40667 | H20: 0 | I20: 0 | J20: 0 | K20: 0
A21: 54622 | B21: 51830 | C21: {=XLOOKUP(B21,Cursos_norm!$A$2:$A$85,Cursos_norm!$E$2:$E$85)} -> 221 | D21: 2011 II | F21: 40681 | G21: 40681 | H21: 0 | I21: 0 | J21: 0 | K21: 0
A22: 54623 | B22: 51831 | C22: {=XLOOKUP(B22,Cursos_norm!$A$2:$A$85,Cursos_norm!$E$2:$E$85)} -> 158 | D22: 2011 I | F22: 40667 | G22: 40667 | H22: 0 | I22: 0 | J22: 0 | K22: 0
A23: 54624 | B23: 51831 | C23: {=XLOOKUP(B23,Cursos_norm!$A$2:$A$85,Cursos_norm!$E$2:$E$85)} -> 158 | D23: 2011 II | F23: 40681 | G23: 40681 | H23: 0 | I23: 0 | J23: 0 | K23: 0
A24: 54625 | B24: 51832 | C24: {=XLOOKUP(B24,Cursos_norm!$A$2:$A$85,Cursos_norm!$E$2:$E$85)} -> 276 | D24: 2012 | F24: 41178 | G24: 41178 | H24: 0 | I24: 0 | J24: 0 | K24: 0
A25: 54626 | B25: 51840 | C25: {=XLOOKUP(B25,Cursos_norm!$A$2:$A$85,Cursos_norm!$E$2:$E$85)} -> 274 | D25: 2012 | F25: 41178 | G25: 41178 | H25: 0 | I25: 0 | J25: 0 | K25: 0
A26: 54627 | B26: 51842 | C26: {=XLOOKUP(B26,Cursos_norm!$A$2:$A$85,Cursos_norm!$E$2:$E$85)} -> 8 | D26: 2013 | F26: 41573 | G26: 41573 | H26: 868 | I26: 0 | J26: 0 | K26: 0
A27: 54628 | B27: 51843 | C27: {=XLOOKUP(B27,Cursos_norm!$A$2:$A$85,Cursos_norm!$E$2:$E$85)} -> 343 | D27: 2013 | F27: 41626 | G27: 41627 | H27: 625 | I27: 0 | J27: 0 | K27: 625
A28: 54629 | B28: 51844 | C28: {=XLOOKUP(B28,Cursos_norm!$A$2:$A$85,Cursos_norm!$E$2:$E$85)} -> 322 | D28: 2013 | F28: 41430 | G28: 41431 | H28: 200 | I28: 0 | J28: 0 | K28: 200
A29: 54630 | B29: 51845 | C29: {=XLOOKUP(B29,Cursos_norm!$A$2:$A$85,Cursos_norm!$E$2:$E$85)} -> 366 | D29: 2014 | F29: 41765 | G29: 41765 | H29: 60 | I29: 0 | J29: 0 | K29: 60
A30: 54631 | B30: 51848 | C30: {=XLOOKUP(B30,Cursos_norm!$A$2:$A$85,Cursos_norm!$E$2:$E$85)} -> 401 | D30: 2015 | F30: 42158 | G30: 42159 | H30: 175 | I30: 0 | J30: 0 | K30: 175
A31: 54632 | B31: 51850 | C31: {=XLOOKUP(B31,Cursos_norm!$A$2:$A$85,Cursos_norm!$E$2:$E$85)} -> 421 | D31: 2015 | F31: 42360 | G31: 42360 | H31: 495 | I31: 0 | J31: 0 | K31: 495
A32: 54633 | B32: 51852 | C32: {=XLOOKUP(B32,Cursos_norm!$A$2:$A$85,Cursos_norm!$E$2:$E$85)} -> 443 | D32: 2015 | F32: 42300 | G32: 42300 | H32: 0 | I32: 0 | J32: 0 | K32: 0
A33: 54634 | B33: 51853 | C33: {=XLOOKUP(B33,Cursos_norm!$A$2:$A$85,Cursos_norm!$E$2:$E$85)} -> 455 | D33: 2016 | F33: 42691 | G33: 42691 | H33: 904 | I33: 0 | J33: 0 | K33: 0
A34: 54635 | B34: 51855 | C34: {=XLOOKUP(B34,Cursos_norm!$A$2:$A$85,Cursos_norm!$E$2:$E$85)} -> 51 | D34: 2016 | F34: 42719 | G34: 42719 | H34: 0 | I34: 0 | J34: 0 | K34: 0
A35: 54636 | B35: 51856 | C35: {=XLOOKUP(B35,Cursos_norm!$A$2:$A$85,Cursos_norm!$E$2:$E$85)} -> 499 | D35: 2017 | F35: 42893 | G35: 42894 | H35: 500 | I35: 0 | J35: 0 | K35: 0
... A64: 57739 | B64: 54600 | C64: {=XLOOKUP(B64,Cursos_norm!$A$2:$A$85,Cursos_norm!$E$2:$E$85)} | D64: 2024 | F64: 45607 | G64: 45646 | H64: 0 | I64: 0 | J64: 0 | K64: 0

Sheet Cursos_norm
A1: cursos_training_id | B1: cursos_company_id | C1: cursos_author_id | D1: cursos_name | E1: cursos_code | F1: cursos_description | G1: cursos_created_at | H1: cursos_updated_at | I1: cursos_external_provider | J1: cursos_external | K1: cursos_total_cost | L1: cursos_fundae_subsidized | M1: cursos_subsidized | N1: cursos_cost | O1: cursos_subsidized_cost | P1: cursos_total_cost_decimal | Q1: cursos_cost_decimal | R1: cursos_subsidized_cost_decimal | S1: cursos_category_ids | T1: cursos_status | U1: cursos_year | V1: cursos_catalog | W1: cursos_competency_ids | X1: cursos_total_training_cost | Y1: cursos_total_training_indirect_cost | Z1: cursos_total_training_salary_cost | AA1: cursos_total_training_subsidized_cost | AB1: cursos_total_participants | AC1: cursos_training_attendance_status | AD1: cursos_valid_for | AE1: cursos_objectives | AF1: cursos_number_of_expired_participants
A2: 51818 | B2: 309418 | C2: 2529034 | D2: ACTUALITZACIONS DELS SISTEMES DE GESTIÓ COMERCIAL ADMINISTRACIÓ I TELEVENDA. | E2: 184 | G2: 2025-04-01T07:25:09.392Z | H2: 2025-04-01T07:25:09.392Z | I2: CIMKEY | J2: VERDADERO | K2: 0 | L2: FALSO | M2: FALSO | N2: 0 | O2: 0 | P2: 0 | Q2: 0 | R2: 0 | S2: [] | T2: draft | U2: 2008 | V2: FALSO | W2: [] | X2: 0 | Y2: 0 | Z2: 0 | AA2: 0 | AB2: 0
A3: 51866 | B3: 309418 | C3: 2529034 | D3: ATMÓSFERAS EXPLOSIVAS: NORMTIVA BÁSICA, CONCEPTOS BÁSICOS SOBRE EXPLOSIONES.... | E3: 295 | G3: 2025-04-01T07:25:24.496Z | H3: 2025-04-02T14:00:32.597Z | I3: EGARSAT - JOSE MIGUEL ORDAS TERRONES | J3: VERDADERO | K3: 0 | L3: FALSO | M3: FALSO | N3: 0 | O3: 0 | P3: 0 | Q3: 0 | R3: 0 | S3: [] | T3: active | U3: 2020 | V3: FALSO | W3: [] | X3: 0 | Y3: 0 | Z3: 0 | AA3: 0 | AB3: 3 | AC3: notstarted
A4: 51859 | B4: 309418 | C4: 2529034 | D4: AUDITOR INTERNO BRC FOOD-07 | E4: 493 | G4: 2025-04-01T07:25:22.345Z | H4: 2025-04-02T14:00:30.307Z | I4: LGAI | J4: VERDADERO | K4: 0 | L4: FALSO | M4: FALSO | N4: 0 | O4: 0 | P4: 0 | Q4: 0 | R4: 0 | S4: [] | T4: active | U4: 2017 | V4: FALSO | W4: [] | X4: 170 | Y4: 0 | Z4: 0 | AA4: 0 | AB4: 1 | AC4: notstarted
A5: 51824 | B5: 309418 | C5: 2529034 | D5: AUDITOR INTERNO DE CALIDAD ISO 9001:2008 | E5: 228 | G5: 2025-04-01T07:25:11.108Z | H5: 2025-04-02T14:00:23.837Z | I5: BUREAU VERITAS FORMACIÓN | J5: VERDADERO | K5: 0 | L5: FALSO | M5: FALSO | N5: 0 | O5: 0 | P5: 0 | Q5: 0 | R5: 0 | S5: [] | T5: active | U5: 2010 | V5: FALSO | W5: [] | X5: 567 | Y5: 0 | Z5: 0 | AA5: 567 | AB5: 1 | AC5: notstarted
A6: 51872 | B6: 309418 | C6: 2529034 | D6: AUDITOR INTERNO EN SISTEMAS DE GESTIÓN DE LA SEG ALIMENTARIA BRC FOOD VERSIÓN | E6: 700 | G6: 2025-04-01T07:25:27.748Z | H6: 2025-04-01T07:25:27.748Z | I6: INTEDYA IBÉRICA, S.L. | J6: VERDADERO | K6: 0 | L6: FALSO | M6: FALSO | N6: 0 | O6: 0 | P6: 0 | Q6: 0 | R6: 0 | S6: [] | T6: draft | U6: 2021 | V6: FALSO | W6: [] | X6: 0 | Y6: 0 | Z6: 0 | AA6: 0 | AB6: 0
A7: 51820 | B7: 309418 | C7: 2529034 | D7: BANKING INGREDIENTS, ENZYMES AND TECHNOLOGY | E7: 200 | G7: 2025-04-01T07:25:09.979Z | H7: 2025-04-02T14:00:22.569Z | I7: ASOCIACIONES QUIMICOS E INGENIEROS IQS | J7: VERDADERO | K7: 0 | L7: FALSO | M7: FALSO | N7: 0 | O7: 0 | P7: 0 | Q7: 0 | R7: 0 | S7: [] | T7: active | U7: 2009 | V7: FALSO | W7: [] | X7: 240 | Y7: 0 | Z7: 0 | AA7: 240 | AB7: 1 | AC7: notstarted
A8: 51881 | B8: 309418 | C8: 2529034 | D8: BIET Meeting 2023 | E8: 792 | G8: 2025-04-01T07:25:30.661Z | H8: 2025-04-02T14:00:36.402Z | I8: AIQS | J8: VERDADERO | K8: 0 | L8: FALSO | M8: FALSO | N8: 0 | O8: 0 | P8: 0 | Q8: 0 | R8: 0 | S8: [] | T8: active | U8: 2023 | V8: FALSO | W8: [] | X8: 900 | Y8: 0 | Z8: 0 | AA8: 0 | AB8: 3 | AC8: notstarted
A9: 51844 | B9: 309418 | C9: 2529034 | D9: BIET'13 | E9: 322 | G9: 2025-04-01T07:25:17.172Z | H9: 2025-04-02T14:00:27.067Z | I9: IQS | J9: VERDADERO | K9: 0 | L9: FALSO | M9: FALSO | N9: 0 | O9: 0 | P9: 0 | Q9: 0 | R9: 0 | S9: [] | T9: active | U9: 2013 | V9: FALSO | W9: [] | X9: 200 | Y9: 0 | Z9: 0 | AA9: 200 | AB9: 1 | AC9: notstarted
A10: 51856 | B10: 309418 | C10: 2529034 | D10: BIET'17 | E10: 499 | G10: 2025-04-01T07:25:21.327Z | H10: 2025-04-02T14:00:29.383Z | I10: IQS | J10: VERDADERO | K10: 0 | L10: FALSO | M10: FALSO | N10: 0 | O10: 0 | P10: 0 | Q10: 0 | R10: 0 | S10: [] | T10: active | U10: 2017 | V10: FALSO | W10: [] | X10: 500 | Y10: 0 | Z10: 0 | AA10: 0 | AB10: 2 | AC10: notstarted
A11: 51848 | B11: 309418 | C11: 2529034 | D11: BIET/15 EUROPEAN MEETING ON BAKING INGREDIENTS, ENZYMES, AND TECHNOLOGY | E11: 401 | G11: 2025-04-01T07:25:18.414Z | H11: 2025-04-02T14:00:27.950Z | I11: A IQS | J11: VERDADERO | K11: 0 | L11: FALSO | M11: FALSO | N11: 0 | O11: 0 | P11: 0 | Q11: 0 | R11: 0 | S11: [] | T11: active | U11: 2015 | V11: FALSO | W11: [] | X11: 175 | Y11: 0 | Z11: 0 | AA11: 175 | AB11: 1 | AC11: notstarted
A12: 51863 | B12: 309418 | C12: 2529034 | D12: BRC VERSIÓN 8 PRINCIPALES CAMBIOS Y CÓMO PROCEDER A SU IMPLANTACIÓNN | E12: 548 | G12: 2025-04-01T07:25:23.601Z | H12: 2025-04-02T14:00:31.528Z | I12: SILLIKER IBERICA SAU | J12: VERDADERO | K12: 0 | L12: FALSO | M12: FALSO | N12: 0 | O12: 0 | P12: 0 | Q12: 0 | R12: 0 | S12: [] | T12: active | U12: 2019 | V12: FALSO | W12: [] | X12: 140 | Y12: 0 | Z12: 0 | AA12: 140 | AB12: 1 | AC12: notstarted
A13: 51846 | B13: 309418 | C13: 2529034 | D13: CARRETILLAS ELEVADORAS | E13: 3 | G13: 2025-04-01T07:25:17.800Z | H13: 2025-04-01T07:25:17.800Z | I13: CIEF ACCIÓ - ORION PREVENCIÓN, S.L. | J13: VERDADERO | K13: 0 | L13: FALSO | M13: FALSO | N13: 0 | O13: 0 | P13: 0 | Q13: 0 | R13: 0 | S13: [] | T13: draft | U13: 2004 | V13: FALSO | W13: [] | X13: 0 | Y13: 0 | Z13: 0 | AA13: 0 | AB13: 0
A14: 51829 | B14: 309418 | C14: 2529034 | D14: CARRETILLAS FRONTALES I RETRACTILES | E14: 233 | G14: 2025-04-01T07:25:12.720Z | H14: 2025-04-01T07:25:12.720Z | I14: CIEF | J14: VERDADERO | K14: 0 | L14: FALSO | M14: FALSO | N14: 0 | O14: 0 | P14: 0 | Q14: 0 | R14: 0 | S14: [] | T14: draft | U14: 2010 | V14: FALSO | W14: [] | X14: 0 | Y14: 0 | Z14: 0 | AA14: 0 | AB14: 0
